<mujoco model="onshape">
  <compiler angle="radian"/>
  <option gravity="0 0 0"/>
  <asset>
    <mesh name="palm_lower" file="assets/palm_lower.stl"/>
    <mesh name="mcp_joint" file="assets/mcp_joint.stl"/>
    <mesh name="pip" file="assets/pip.stl"/>
    <mesh name="dip" file="assets/dip.stl"/>
    <mesh name="fingertip" file="assets/fingertip.stl"/>
    <mesh name="thumb_pip" file="assets/thumb_pip.stl"/>
    <mesh name="thumb_dip" file="assets/thumb_dip.stl"/>
    <mesh name="thumb_fingertip" file="assets/thumb_fingertip.stl"/>
    <mesh name="cylinder_s" file="assets/cylinder_s.stl" scale="0.001 0.001 0.001"/>
  </asset>
  <actuator>
    <position name="actuator_joint_0" joint="0" kv="0.1" kp="2" ctrlrange="-1 1"/>
    <position name="actuator_joint_1" joint="1" kv="0.1" kp="2" ctrlrange="-1 1"/>
    <position name="actuator_joint_2" joint="2" kv="0.1" kp="2" ctrlrange="-1 1"/>
    <position name="actuator_joint_3" joint="3" kv="0.1" kp="2" ctrlrange="-1 1"/>
    
    <position name="actuator_joint_4" joint="4" kv="0.1" kp="2" ctrlrange="-1 1"/>
    <position name="actuator_joint_5" joint="5" kv="0.1" kp="2" ctrlrange="-1 1"/>
    <position name="actuator_joint_6" joint="6" kv="0.1" kp="2" ctrlrange="-1 1"/>
    <position name="actuator_joint_7" joint="7" kv="0.1" kp="2" ctrlrange="-1 1"/>
    
    <position name="actuator_joint_8" joint="8" kv="0.1" kp="2" ctrlrange="-1 1"/>
    <position name="actuator_joint_9" joint="9" kv="0.1" kp="2" ctrlrange="-1 1"/>
    <position name="actuator_joint_10" joint="10" kv="0.1" kp="2" ctrlrange="-1 1"/>
    <position name="actuator_joint_11" joint="11" kv="0.1" kp="2" ctrlrange="-1 1"/>
    
    <position name="actuator_joint_12" joint="12" kv="0.1" kp="2" ctrlrange="-1 2"/>
    <position name="actuator_joint_13" joint="13" kv="0.1" kp="2" ctrlrange="-1 1"/>
    <position name="actuator_joint_14" joint="14" kv="0.1" kp="2" ctrlrange="-1 1"/>
    <position name="actuator_joint_15" joint="15" kv="0.1" kp="2" ctrlrange="-1 2"/>
  </actuator>
  <worldbody>
    <body name="leap_head" pos="0 0 0" quat="0 1 0 0">
      <geom pos="-0.0200952 0.0257578 -0.0347224" type="mesh" rgba="0.603922 0.14902 0.14902 1" mesh="palm_lower" contype="1" conaffinity="0"/>
      
      <body name="mcp_joint" pos="-0.00709525 0.0230578 -0.0187224" quat="0.5 0.5 0.5 -0.5">
        <inertial pos="0 0 0" quat="0.388585 0.626468 -0.324549 0.592628" mass="0.044" diaginertia="1.47756e-05 1.31982e-05 6.0802e-06"/>
        <joint name="1" pos="0 0 0" axis="0 0 -1" range="-0.314 2.23" actuatorfrcrange="-0.95 0.95" damping="0.1"/>
        <geom pos="0.0084069 0.00776624 0.0146574" quat="1 0 0 0" type="mesh" rgba="0.866667 0.866667 0.0509804 1" mesh="mcp_joint" contype="1" conaffinity="0"/>
        <body name="pip" pos="-0.0122 0.0381 0.0145" quat="0.5 -0.5 -0.5 0.5">
          <inertial pos="0 0 0" quat="0.709913 0.704273 -0.000363156 0.00475427" mass="0.032" diaginertia="4.7981e-06 4.23406e-06 2.86184e-06"/>
          <joint name="0" pos="0 0 0" axis="0 0 -1" range="-1.047 1.047" actuatorfrcrange="-0.95 0.95" damping="0.1"/>
          <geom pos="0.00964336 0.0003 0.000784034" quat="0.5 -0.5 -0.5 -0.5" type="mesh" rgba="0.74902 0.74902 0.74902 1" mesh="pip" contype="1" conaffinity="0"/>
          <body name="dip" pos="0.015 0.0143 -0.013" quat="0.5 0.5 -0.5 0.5">
            <inertial pos="0 0 0" quat="-0.252689 0.659216 0.238844 0.666735" mass="0.037" diaginertia="6.68256e-06 6.24841e-06 5.02002e-06"/>
            <joint name="2" pos="0 0 0" axis="0 0 -1" range="-0.506 1.885" actuatorfrcrange="-0.95 0.95" damping="0.1"/>
            <geom pos="0.0211334 -0.00843212 0.00978509" quat="0 -1 0 0" type="mesh" rgba="0.866667 0.866667 0.0509804 1" mesh="dip" contype="1" conaffinity="0"/>
            <body name="fingertip" pos="-4.08806e-09 -0.0361 0.0002">
              <inertial pos="0 0 0" quat="0.706755 0.706755 0.0223155 0.0223155" mass="0.016" diaginertia="3.37527e-06 2.863e-06 1.54873e-06"/>
              <joint name="3" pos="0 0 0" axis="0 0 -1" range="-0.366 2.042" actuatorfrcrange="-0.95 0.95" damping="0.1"/>
              <geom pos="0.0132864 -0.00611424 0.0145" quat="0 1 0 0" type="mesh" rgba="0.866667 0.866667 0.0509804 1" mesh="fingertip" contype="1" conaffinity="0"/>
              <body name="finger_end_1" pos="0 -0.03 0.02">
                <geom pos="0 0 0" euler="0 0 0" type="sphere" size="0.018" rgba="0 1 1 1" contype="0" conaffinity="0"/>
              </body>
            </body>
          </body>
        </body>
      </body>
      <body name="mcp_joint_2" pos="-0.00709525 -0.0223922 -0.0187224" quat="0.5 0.5 0.5 -0.5">
        <inertial pos="0 0 0" quat="0.388585 0.626468 -0.324549 0.592628" mass="0.044" diaginertia="1.47756e-05 1.31982e-05 6.0802e-06"/>
        <joint name="5" pos="0 0 0" axis="0 0 -1" range="-0.314 2.23" actuatorfrcrange="-0.95 0.95" damping="0.1"/>
        <geom pos="0.0084069 0.00776624 0.0146574" quat="1 0 0 0" type="mesh" rgba="0.866667 0.866667 0.0509804 1" mesh="mcp_joint" contype="1" conaffinity="0"/>
        <body name="pip_2" pos="-0.0122 0.0381 0.0145" quat="0.5 -0.5 -0.5 0.5">
          <inertial pos="0 0 0" quat="0.709913 0.704273 -0.000363156 0.00475427" mass="0.032" diaginertia="4.7981e-06 4.23406e-06 2.86184e-06"/>
          <joint name="4" pos="0 0 0" axis="0 0 -1" range="-1.047 1.047" actuatorfrcrange="-0.95 0.95" damping="0.1"/>
          <geom pos="0.00964336 0.0003 0.000784034" quat="0.5 -0.5 -0.5 -0.5" type="mesh" rgba="0.74902 0.74902 0.74902 1" mesh="pip" contype="1" conaffinity="0"/>
          <body name="dip_2" pos="0.015 0.0143 -0.013" quat="0.5 0.5 -0.5 0.5">
            <inertial pos="0 0 0" quat="-0.252689 0.659216 0.238844 0.666735" mass="0.037" diaginertia="6.68256e-06 6.24841e-06 5.02002e-06"/>
            <joint name="6" pos="0 0 0" axis="0 0 -1" range="-0.506 1.885" actuatorfrcrange="-0.95 0.95" damping="0.1"/>
            <geom pos="0.0211334 -0.00843212 0.00978509" quat="0 -1 0 0" type="mesh" rgba="0.866667 0.866667 0.0509804 1" mesh="dip" contype="1" conaffinity="0"/>
            <body name="fingertip_2" pos="0 -0.0361 0.0002">
              <inertial pos="0 0 0" quat="0.706755 0.706755 0.0223155 0.0223155" mass="0.016" diaginertia="3.37527e-06 2.863e-06 1.54873e-06"/>
              <joint name="7" pos="0 0 0" axis="0 0 -1" range="-0.366 2.042" actuatorfrcrange="-0.95 0.95" damping="0.1"/>
              <geom pos="0.0132864 -0.00611424 0.0145" quat="0 1 0 0" type="mesh" rgba="0.866667 0.866667 0.0509804 1" mesh="fingertip" contype="1" conaffinity="0"/>
              <body name="finger_end_2" pos="0 -0.035 0.015">
                <geom pos="0 0 0" euler="0 0 0" type="sphere" size="0.018" rgba="0 1 1 1" contype="0" conaffinity="0"/>
              </body>
            </body>
          </body>
        </body>
      </body>
      <body name="mcp_joint_3" pos="-0.00709525 -0.0678422 -0.0187224" quat="0.5 0.5 0.5 -0.5">
        <inertial pos="0 0 0" quat="0.388585 0.626468 -0.324549 0.592628" mass="0.044" diaginertia="1.47756e-05 1.31982e-05 6.0802e-06"/>
        <joint name="9" pos="0 0 0" axis="0 0 -1" range="-0.314 2.23" actuatorfrcrange="-0.95 0.95" damping="0.1"/>
        <geom pos="0.0084069 0.00776624 0.0146574" quat="1 0 0 0" type="mesh" rgba="0.866667 0.866667 0.0509804 1" mesh="mcp_joint" contype="1" conaffinity="0"/>
        <body name="pip_3" pos="-0.0122 0.0381 0.0145" quat="0.5 -0.5 -0.5 0.5">
          <inertial pos="0 0 0" quat="0.709913 0.704273 -0.000363156 0.00475427" mass="0.032" diaginertia="4.7981e-06 4.23406e-06 2.86184e-06"/>
          <joint name="8" pos="0 0 0" axis="0 0 -1" range="-1.047 1.047" actuatorfrcrange="-0.95 0.95" damping="0.1"/>
          <geom pos="0.00964336 0.0003 0.000784034" quat="0.5 -0.5 -0.5 -0.5" type="mesh" rgba="0.74902 0.74902 0.74902 1" mesh="pip" contype="1" conaffinity="0"/>
          <body name="dip_3" pos="0.015 0.0143 -0.013" quat="0.5 0.5 -0.5 0.5">
            <inertial pos="0 0 0" quat="-0.252689 0.659216 0.238844 0.666735" mass="0.037" diaginertia="6.68256e-06 6.24841e-06 5.02002e-06"/>
            <joint name="10" pos="0 0 0" axis="0 0 -1" range="-0.506 1.885" actuatorfrcrange="-0.95 0.95" damping="0.1"/>
            <geom pos="0.0211334 -0.00843212 0.00978509" quat="0 -1 0 0" type="mesh" rgba="0.866667 0.866667 0.0509804 1" mesh="dip" contype="1" conaffinity="0"/>
            <body name="fingertip_3" pos="0 -0.0361 0.0002">
              <inertial pos="0 0 0" quat="0.706755 0.706755 0.0223155 0.0223155" mass="0.016" diaginertia="3.37527e-06 2.863e-06 1.54873e-06"/>
              <joint name="11" pos="0 0 0" axis="0 0 -1" range="-0.366 2.042" actuatorfrcrange="-0.95 0.95" damping="0.1"/>
              <geom pos="0.0132864 -0.00611424 0.0145" quat="0 1 0 0" type="mesh" rgba="0.866667 0.866667 0.0509804 1" mesh="fingertip" contype="1" conaffinity="0"/>
            </body>
          </body>
        </body>
      </body>
      <body name="pip_4" pos="-0.0693952 -0.00124224 -0.0216224" quat="0.707107 0 0.707107 0">
        <inertial pos="0 0 0" quat="0.709913 0.704273 -0.000363156 0.00475427" mass="0.032" diaginertia="4.7981e-06 4.23406e-06 2.86184e-06"/>
        <joint name="12" pos="0 0 0" axis="0 0 -1" range="-0.349 3.094" actuatorfrcrange="-0.95 0.95" damping="0.1"/>
        <geom pos="-0.00535664 0.0003 0.000784034" quat="0.5 -0.5 -0.5 -0.5" type="mesh" rgba="0.74902 0.74902 0.74902 1" mesh="pip" contype="1" conaffinity="0"/>
        <body name="thumb_pip" pos="0 0.0143 -0.013" quat="0.5 0.5 -0.5 0.5">
          <inertial pos="0 0 0" mass="0.003" diaginertia="5.93e-07 5.49e-07 2.24e-07"/>
          <joint name="13" pos="0 0 0" axis="0 0 -1" range="-0.47 2.443" actuatorfrcrange="-0.95 0.95" damping="0.1"/>
          <geom pos="0.0119619 0 -0.0158526" quat="0.707107 0.707107 0 0" type="mesh" rgba="0.866667 0.866667 0.0509804 1" mesh="thumb_pip" contype="1" conaffinity="0"/>
          <body name="thumb_dip" pos="0 0.0145 -0.017" quat="0.707107 -0.707107 0 0">
            <inertial pos="0 0 0" quat="0.708624 0.704906 0.00637342 0.0303153" mass="0.038" diaginertia="8.48742e-06 7.67823e-06 3.82835e-06"/>
            <joint name="14" pos="0 0 0" axis="0 0 -1" range="-1.2 1.9" actuatorfrcrange="-0.95 0.95" damping="0.1"/>
            <geom pos="0.0439687 0.057953 -0.00862868" quat="1 0 0 0" type="mesh" rgba="0.866667 0.866667 0.0509804 1" mesh="thumb_dip" contype="1" conaffinity="0"/>
            <body name="thumb_fingertip" pos="0 0.0466 0.0002" quat="0 0 0 1">
              <inertial pos="0 0 0" quat="0.704307 0.709299 0.006848 -0.0282727" mass="0.049" diaginertia="2.03882e-05 1.98443e-05 4.32049e-06"/>
              <joint name="15" pos="0 0 0" axis="0 0 -1" range="-1.34 1.88" actuatorfrcrange="-0.95 0.95" damping="0.1"/>
              <geom pos="0.0625595 0.0784597 0.0489929" type="mesh" rgba="0.603922 0.14902 0.14902 1" mesh="thumb_fingertip" contype="1" conaffinity="0"/>
              <body name="finger_end" pos="0 -0.03 -0.02">
                <geom pos="0 0 0" euler="0 0 0" type="sphere" size="0.018" rgba="0 1 1 1" contype="0" conaffinity="0"/>
              </body>
            </body>
          </body>
        </body>
      </body>

      <body name="cylinder" pos="-0.05 -0.05 -0.13">
        <geom type="mesh" mesh="cylinder_s" pos="0 0 0" quat="1 0 0 0" mass="0.5" contype="0" conaffinity="1"/>
        <joint name="target_cx" type="slide" pos="0 0 0" axis="1 0 0" limited="true" range="-1 1"></joint>
        <joint name="target_cy" type="slide" pos="0 0 0" axis="0 1 0" limited="true" range="-1 1"></joint>
        <joint name="target_cz" type="slide" pos="0 0 0" axis="0 0 1" limited="true" range="-1 1"></joint>
        <body name="red_ball" pos="0.03 0.08 0.03">
          <geom pos="0 0 0" euler="0 0 0" type="sphere" size="0.008" rgba="1 0 0 1" contype="0" conaffinity="0"/>
        </body>
      </body>

      <body name="target_obj" pos="0.03 0.03 -0.12" euler="0 0 0">
        <geom pos="0 0 0" euler="0 0 0" type="sphere" size="0.008" rgba="0 1 0 1" contype="0" conaffinity="0"/>
        <joint name="target_tx" type="slide" pos="0 0 0" axis="1 0 0" limited="true" range="-1 1"></joint>
        <joint name="target_ty" type="slide" pos="0 0 0" axis="0 1 0" limited="true" range="-1 1"></joint>
        <joint name="target_tz" type="slide" pos="0 0 0" axis="0 0 1" limited="true" range="-1 1"></joint>
      </body>
    </body>
  </worldbody>
  <keyframe>
    <key qpos=' 0.97072 0.14658 0.462355 0.19988 0.99616 -0.01047 0.40258 0.28416 -0.314 0.14658 0 0 1.51022 0 -0.2235 0.8657 0 -0.01 -0.03 0 0 0'/>
  </keyframe>
</mujoco>
